<mujoco model="asimov">
  <default>
    <default class="robot">
      <default class="motor">
        <joint/>
        <motor/>
      </default>
      <default class="visual">
        <geom material="visual_grey" contype="0" conaffinity="0" group="2"/>
      </default>
      <default class="collision">
        <geom material="collision_grey" condim="3" contype="0" conaffinity="1"
              priority="1" group="1" solref="0.005 1" solimp="0.99 0.999 1e-05"
              friction="1 0.01 0.01"/>
      </default>
    </default>
  </default>


  <compiler angle="radian" />

  <asset>
    <material name="visual_grey" rgba="0.6 0.6 0.6 1"/>       <!-- main robot color -->
    <material name="collision_grey" rgba="0.3 0.3 0.3 1"/>    <!-- for collisions -->
    <material name="dark_gray" rgba="0.1098 0.1098 0.1098 1"/>

    <mesh name="pelvis_link.STL" file="pelvis_link.STL"/>
    <mesh name="left_hip_pitch_link.STL" file="left_hip_pitch_link.STL"/>
    <mesh name="left_hip_roll_link.STL" file="left_hip_roll_link.STL"/>
    <mesh name="left_hip_yaw_link.STL" file="left_hip_yaw_link.STL"/>
    <mesh name="left_knee_link.STL" file="left_knee_link.STL"/>
    <mesh name="left_ankle_pitch_link.STL" file="left_ankle_pitch_link.STL"/>
    <mesh name="left_ankle_roll_link.STL" file="left_ankle_roll_link.STL"/>
    <mesh name="right_hip_pitch_link.STL" file="right_hip_pitch_link.STL"/>
    <mesh name="right_hip_roll_link.STL" file="right_hip_roll_link.STL"/>
    <mesh name="right_hip_yaw_link.STL" file="right_hip_yaw_link.STL"/>
    <mesh name="right_knee_link.STL" file="right_knee_link.STL"/>
    <mesh name="right_ankle_pitch_link.STL" file="right_ankle_pitch_link.STL"/>
    <mesh name="right_ankle_roll_link.STL" file="right_ankle_roll_link.STL"/>
  </asset>


  <worldbody>
    <body name="asimov_base" pos="0.00000000 0.00000000 0.70899500" quat="1 0 0 0" childclass="robot">
      <freejoint name="floating_base" />
      <body name="pelvis_link" pos="0 0 0" quat="1 0 0 0">
        <inertial pos="-0.00071228 -3.4719E-07 -0.073826" quat="1.0 0.0 0.0 0.0" mass="3.3125" diaginertia="0.0033117 0.0028238 0.003564" />
       <site name="imu" pos="0.0 0.0 0.0" size="0.01" rgba="1 0 0 1" type="sphere" />

        <geom name="pelvis_link_collision" pos="0 0 0" quat="1.0 0.0 0.0 0.0" type="mesh" mesh="pelvis_link.STL" class="collision" />
        <geom name="pelvis_link_visual" pos="0 0 0" quat="1.0 0.0 0.0 0.0" type="mesh" mesh="pelvis_link.STL" class="visual" />
        <body name="left_hip_pitch_link" pos="0 0.056569 -0.10543" quat="1.0 0.0 0.0 0.0">
          <joint name="left_hip_pitch_joint" type="hinge" ref="0.0" class="motor" range="-3.1416 1.0472" axis="0 -0.70711 0.70711" />
          <site name="left_hip_pitch_joint_site" pos="0 0 0" quat="1 0 0 0" />
          <inertial pos="0.00329 0.045581 -0.045581" quat="1.0 0.0 0.0 0.0" mass="0.92565" diaginertia="0.00053984 0.00066418 0.00066419" />
          <geom name="left_hip_pitch_link_collision" pos="0 0 0" quat="1.0 0.0 0.0 0.0" type="mesh" mesh="left_hip_pitch_link.STL" class="collision" />
          <geom name="left_hip_pitch_link_visual" pos="0 0 0" quat="1.0 0.0 0.0 0.0" type="mesh" mesh="left_hip_pitch_link.STL" class="visual" />
          <body name="left_hip_roll_link" pos="0 0.051265 -0.051265" quat="1.0 0.0 0.0 0.0">
            <joint name="left_hip_roll_joint" type="hinge" ref="0.0" class="motor" range="-2.97 0.52" axis="-1 0 0" />
            <site name="left_hip_roll_joint_site" pos="0 0 0" quat="1 0 0 0" />
            <inertial pos="0.01525 -0.00017964 -0.061059" quat="1.0 0.0 0.0 0.0" mass="0.83528" diaginertia="0.00054401 0.00063585 0.00038113" />
            <geom name="left_hip_roll_link_collision" pos="0 0 0" quat="1.0 0.0 0.0 0.0" type="mesh" mesh="left_hip_roll_link.STL" class="collision" />
            <geom name="left_hip_roll_link_visual" pos="0 0 0" quat="1.0 0.0 0.0 0.0" type="mesh" mesh="left_hip_roll_link.STL" class="visual" />
            <body name="left_hip_yaw_link" pos="0 0 -0.09275" quat="1.0 0.0 0.0 0.0">
              <joint name="left_hip_yaw_joint" type="hinge" ref="0.0" class="motor" range="-2.76 2.76" axis="0 0 -1" />
              <site name="left_hip_yaw_joint_site" pos="0 0 0" quat="1 0 0 0" />
              <inertial pos="7.0761E-05 0.00031363 -0.11496" quat="1.0 0.0 0.0 0.0" mass="1.2782" diaginertia="0.0024302 0.0025065 0.0007566" />
              <geom name="left_hip_yaw_link_collision" pos="0 0 0" quat="1.0 0.0 0.0 0.0" type="mesh" mesh="left_hip_yaw_link.STL" class="collision" />
              <geom name="left_hip_yaw_link_visual" pos="0 0 0" quat="1.0 0.0 0.0 0.0" type="mesh" mesh="left_hip_yaw_link.STL" class="visual" />
              <body name="left_knee_link" pos="0 0 -0.15489" quat="1.0 0.0 0.0 0.0">
                <joint name="left_knee_joint" type="hinge" ref="0.0" class="motor" range="-2 0.09" axis="0 -1 0" />
                <site name="left_knee_joint_site" pos="0 0 0" quat="1 0 0 0" />
                <inertial pos="-0.0025212 0.00051084 -0.10659" quat="1.0 0.0 0.0 0.0" mass="2.2481" diaginertia="0.0093797 0.0095623 0.0023403" />
                <geom name="left_knee_link_collision" pos="0 0 0" quat="1.0 0.0 0.0 0.0" type="mesh" mesh="left_knee_link.STL" class="collision" />
                <geom name="left_knee_link_visual" pos="0 0 0" quat="1.0 0.0 0.0 0.0" type="mesh" mesh="left_knee_link.STL" class="visual" />
                <body name="left_ankle_pitch_link" pos="0 0 -0.29466" quat="1.0 0.0 0.0 0.0">
                  <joint name="left_ankle_pitch_joint" type="hinge" ref="0.0" class="motor" range="-0.36 0.36" axis="0 1 0" />
                  <site name="left_ankle_pitch_joint_site" pos="0 0 0" quat="1 0 0 0" />
                  <inertial pos="-0.0011784 -2.4418E-08 -0.0061736" quat="1.0 0.0 0.0 0.0" mass="0.27369" diaginertia="6.4443e-05 8.1172e-05 4.7493e-05" />
                  <geom name="left_ankle_pitch_link_collision" pos="0 0 0" quat="1.0 0.0 0.0 0.0" type="mesh" mesh="left_ankle_pitch_link.STL" class="collision" />
                  <geom name="left_ankle_pitch_link_visual" pos="0 0 0" quat="1.0 0.0 0.0 0.0" type="mesh" mesh="left_ankle_pitch_link.STL" class="visual" />
                  <body name="left_ankle_roll_link" pos="-0.0015 0 -0.01" quat="1.0 0.0 0.0 0.0">
                    <joint name="left_ankle_roll_joint" type="hinge" ref="0.0" class="motor" range="-0.261 0.261" axis="-1 0 0" />
                    <site name="left_ankle_roll_joint_site" pos="0 0 0" quat="1 0 0 0" />
                    <inertial pos="0.081381 -0.00033806 -0.015509" quat="1.0 0.0 0.0 0.0" mass="0.61291" diaginertia="0.00031968 0.00045036 0.00070504" />
                    <geom name="left_ankle_roll_link_collision" pos="0 0 0" quat="1.0 0.0 0.0 0.0" type="mesh" mesh="left_ankle_roll_link.STL" class="collision" />
                    <geom name="left_ankle_roll_link_visual" pos="0 0 0" quat="1.0 0.0 0.0 0.0" type="mesh" mesh="left_ankle_roll_link.STL" class="visual" />
                  </body>
                </body>
              </body>
            </body>
          </body>
        </body>
        <body name="right_hip_pitch_link" pos="0 -0.056569 -0.10543" quat="1.0 0.0 0.0 0.0">
          <joint name="right_hip_pitch_joint" type="hinge" ref="0.0" class="motor" range="-1.0472 3.1416" axis="0 0.70711 0.70711" />
          <site name="right_hip_pitch_joint_site" pos="0 0 0" quat="1 0 0 0" />
          <inertial pos="0.0032901 -0.045581 -0.045581" quat="1.0 0.0 0.0 0.0" mass="0.92565" diaginertia="0.00053984 0.00066418 0.00066418" />
          <geom name="right_hip_pitch_link_collision" pos="0 0 0" quat="1.0 0.0 0.0 0.0" type="mesh" mesh="right_hip_pitch_link.STL" class="collision" />
          <geom name="right_hip_pitch_link_visual" pos="0 0 0" quat="1.0 0.0 0.0 0.0" type="mesh" mesh="right_hip_pitch_link.STL" class="visual" />
          <body name="right_hip_roll_link" pos="0 -0.051265 -0.051265" quat="1.0 0.0 0.0 0.0">
            <joint name="right_hip_roll_joint" type="hinge" ref="0.0" class="motor" range="-0.52 2.97" axis="-1 0 0" />
            <site name="right_hip_roll_joint_site" pos="0 0 0" quat="1 0 0 0" />
            <inertial pos="0.01525 0.0001796 -0.061059" quat="1.0 0.0 0.0 0.0" mass="0.83528" diaginertia="0.00054401 0.00063584 0.00038113" />
            <geom name="right_hip_roll_link_collision" pos="0 0 0" quat="1.0 0.0 0.0 0.0" type="mesh" mesh="right_hip_roll_link.STL" class="collision" />
            <geom name="right_hip_roll_link_visual" pos="0 0 0" quat="1.0 0.0 0.0 0.0" type="mesh" mesh="right_hip_roll_link.STL" class="visual" />
            <body name="right_hip_yaw_link" pos="0 0 -0.09275" quat="1.0 0.0 0.0 0.0">
              <joint name="right_hip_yaw_joint" type="hinge" ref="0.0" class="motor" range="-2.76 2.76" axis="0 0 -1" />
              <site name="right_hip_yaw_joint_site" pos="0 0 0" quat="1 0 0 0" />
              <inertial pos="7.1067E-05 -0.00031339 -0.11496" quat="1.0 0.0 0.0 0.0" mass="1.2782" diaginertia="0.0024302 0.0025065 0.0007566" />
              <geom name="right_hip_yaw_link_collision" pos="0 0 0" quat="1.0 0.0 0.0 0.0" type="mesh" mesh="right_hip_yaw_link.STL" class="collision" />
              <geom name="right_hip_yaw_link_visual" pos="0 0 0" quat="1.0 0.0 0.0 0.0" type="mesh" mesh="right_hip_yaw_link.STL" class="visual" />
              <body name="right_knee_link" pos="0 0 -0.15489" quat="1.0 0.0 0.0 0.0">
                <joint name="right_knee_joint" type="hinge" ref="0.0" class="motor" range="-0.09 2" axis="0 1 0" />
                <site name="right_knee_joint_site" pos="0 0 0" quat="1 0 0 0" />
                <inertial pos="-0.0025213 -0.00051098 -0.10659" quat="1.0 0.0 0.0 0.0" mass="2.2481" diaginertia="0.0093796 0.0095623 0.0023403" />
                <geom name="right_knee_link_collision" pos="0 0 0" quat="1.0 0.0 0.0 0.0" type="mesh" mesh="right_knee_link.STL" class="collision" />
                <geom name="right_knee_link_visual" pos="0 0 0" quat="1.0 0.0 0.0 0.0" type="mesh" mesh="right_knee_link.STL" class="visual" />
                <body name="right_ankle_pitch_link" pos="0 0 -0.29466" quat="1.0 0.0 0.0 0.0">
                  <joint name="right_ankle_pitch_joint" type="hinge" ref="0.0" class="motor" range="-0.36 0.36" axis="0 -1 0" />
                  <site name="right_ankle_pitch_joint_site" pos="0 0 0" quat="1 0 0 0" />
                  <inertial pos="-0.0011784 5.9726E-08 -0.0061735" quat="1.0 0.0 0.0 0.0" mass="0.27369" diaginertia="6.4442e-05 8.1171e-05 4.7493e-05" />
                  <geom name="right_ankle_pitch_link_collision" pos="0 0 0" quat="1.0 0.0 0.0 0.0" type="mesh" mesh="right_ankle_pitch_link.STL" class="collision" />
                  <geom name="right_ankle_pitch_link_visual" pos="0 0 0" quat="1.0 0.0 0.0 0.0" type="mesh" mesh="right_ankle_pitch_link.STL" class="visual" />
                  <body name="right_ankle_roll_link" pos="-0.0015 0 -0.01" quat="1.0 0.0 0.0 0.0">
                    <joint name="right_ankle_roll_joint" type="hinge" ref="0.0" class="motor" range="-0.261 0.261" axis="-1 0 0" />
                    <site name="right_ankle_roll_joint_site" pos="0 0 0" quat="1 0 0 0" />
                    <inertial pos="0.081347 0.00027474 -0.015509" quat="1.0 0.0 0.0 0.0" mass="0.61291" diaginertia="0.0003197 0.00045029 0.00070498" />
                    <geom name="right_ankle_roll_link_collision" pos="0 0 0" quat="1.0 0.0 0.0 0.0" type="mesh" mesh="right_ankle_roll_link.STL" class="collision" />
                    <geom name="right_ankle_roll_link_visual" pos="0 0 0" quat="1.0 0.0 0.0 0.0" type="mesh" mesh="right_ankle_roll_link.STL" class="visual" />
                  </body>
                </body>
              </body>
            </body>
          </body>
        </body>
      </body>
      <site name="world_site" pos="0 0 0" quat="1 0 0 0" />
      <camera name="front_camera" mode="track" fovy="90.0" quat="4.329780281177467e-17 4.329780281177466e-17 0.7071067811865475 0.7071067811865476" pos="0.0 2.0 0.5" />
      <camera name="side_camera" mode="track" fovy="90.0" quat="-0.5 -0.4999999999999999 0.5 0.5000000000000001" pos="-2.0 0.0 0.5" />
    </body>
  </worldbody>


  <contact>
    <exclude body1="pelvis_link" body2="left_hip_pitch_link" />
    <exclude body1="left_hip_pitch_link" body2="left_hip_roll_link" />
    <exclude body1="left_hip_roll_link" body2="left_hip_yaw_link" />
    <exclude body1="left_hip_yaw_link" body2="left_knee_link" />
    <exclude body1="left_knee_link" body2="left_ankle_pitch_link" />
    <exclude body1="left_ankle_pitch_link" body2="left_ankle_roll_link" />
    <exclude body1="pelvis_link" body2="right_hip_pitch_link" />
    <exclude body1="right_hip_pitch_link" body2="right_hip_roll_link" />
    <exclude body1="right_hip_roll_link" body2="right_hip_yaw_link" />
    <exclude body1="right_hip_yaw_link" body2="right_knee_link" />
    <exclude body1="right_knee_link" body2="right_ankle_pitch_link" />
    <exclude body1="right_ankle_pitch_link" body2="right_ankle_roll_link" />
  </contact>


  <sensor>
    <!-- IMU sensors at pelvis -->
    <gyro name="imu_gyro" site="imu" noise="0.01" cutoff="34.9" />
    <accelerometer name="imu_accel" site="imu" noise="0.01" cutoff="157" />
    <framequat name="imu_quat" objtype="site" objname="imu" />
    <framelinvel name="imu_lin_vel" objtype="site" objname="imu" />
    <frameangvel name="imu_ang_vel" objtype="site" objname="imu" />

    <!-- Angular momentum sensor for whole robot -->
    <subtreeangmom name="root_angmom" body="asimov_base" />

    <!-- Joint site sensors (for debugging) -->
    <framepos name="left_hip_pitch_joint_site_pos" objtype="site" objname="left_hip_pitch_joint_site" />
    <framequat name="left_hip_pitch_joint_site_quat" objtype="site" objname="left_hip_pitch_joint_site" />
    <framelinvel name="left_hip_pitch_joint_site_linvel" objtype="site" objname="left_hip_pitch_joint_site" />
    <frameangvel name="left_hip_pitch_joint_site_angvel" objtype="site" objname="left_hip_pitch_joint_site" />
    <velocimeter name="left_hip_pitch_joint_site_vel" site="left_hip_pitch_joint_site" />
  </sensor>
</mujoco>